<?xml version="1.0" ?>
<robot xmlns:xacro="http://www.ros.org/wiki/xacro">
	<joint name="HeadYaw" type="revolute">
		<parent link="torso"/>
		<child link="Neck"/>
		<origin rpy="0 0 0" xyz="0 0 0.1265"/>
		<axis xyz="0 0 1.0"/>
		<limit effort="1.2" lower="-2.08567" upper="2.08567" velocity="8.26797"/>
	</joint>
	<link name="Neck">
		<visual>
			<geometry>
				<mesh filename="file:///home/marguedas/.ros/nao_meshes/meshes/V40/visual/collada/Neck.dae" scale="0.1 0.1 0.1"/>
			</geometry>
		</visual>
		<collision>
			<geometry>
				<mesh filename="file:///home/marguedas/.ros/nao_meshes/meshes/V40/visual/collada/Neck.dae" scale="0.1 0.1 0.1"/>
			</geometry>
		</collision>
		<inertial>
			<mass value="0.06442"/>
			<inertia ixx="7.4993e-05" ixy="1.57e-09" ixz="-1.834e-08" iyy="7.6e-05" iyz="-5.295e-08" izz="5.53373e-06"/>
			<origin rpy="0 0 0" xyz="-1e-05 0 -0.02742"/>
		</inertial>
	</link>
	<joint name="HeadPitch" type="revolute">
		<parent link="Neck"/>
		<child link="Head"/>
		<origin rpy="0 0 0" xyz="0 0 0"/>
		<axis xyz="0 1.0 0"/>
		<limit effort="1.2" lower="-0.671952" upper="0.514872" velocity="7.19407"/>
	</joint>
	<link name="Head">
		<visual>
			<geometry>
				<mesh filename="file:///home/marguedas/.ros/nao_meshes/meshes/V40/visual/collada/Head.dae" scale="0.1 0.1 0.1"/>
			</geometry>
		</visual>
		<collision>
			<geometry>
				<mesh filename="file:///home/marguedas/.ros/nao_meshes/meshes/V40/visual/collada/Head.dae" scale="0.1 0.1 0.1"/>
			</geometry>
		</collision>
		<inertial>
			<mass value="0.60533"/>
			<inertia ixx="0.0026313" ixy="8.78814e-06" ixz="4.09847e-05" iyy="0.00249112" iyz="-2.99579e-05" izz="0.000985736"/>
			<origin rpy="0 0 0" xyz="-0.00112 0 0.05258"/>
		</inertial>
	</link>
	<joint name="CameraTop_joint" type="fixed">
		<parent link="Head"/>
		<child link="CameraTop_frame"/>
		<origin rpy="0 0 0" xyz="0.0539 0 0.0679"/>
	</joint>
	<link name="CameraTop_frame"/>
	<joint name="gaze_joint" type="fixed">
		<parent link="CameraTop_frame"/>
		<child link="gaze"/>
		<origin rpy="0 0 0" xyz="0 0 0"/>
	</joint>
	<link name="gaze"/>
</robot>
