<?xml version="1.0" ?>
<!-- =================================================================================== -->
<!-- |    This document was autogenerated by xacro from /tmp/naorobot.xacro            | -->
<!-- |    EDITING THIS FILE BY HAND IS NOT RECOMMENDED                                 | -->
<!-- =================================================================================== -->
<robot name="naoH25V40" xmlns:xacro="http://www.ros.org/wiki/xacro">
  <joint name="HeadYaw" type="revolute">
    <parent link="torso"/>
    <child link="Neck"/>
    <origin rpy="0 0 0" xyz="0 0 0.1265"/>
    <axis xyz="0 0 1.0"/>
    <limit effort="1.2" lower="-2.08567" upper="2.08567" velocity="8.26797"/>
  </joint>
  <link name="Neck">
    <visual>
      <geometry>
        <mesh filename="file:///home/marguedas/.ros/nao_meshes/meshes/V40/visual/collada/Neck.dae" scale="0.1 0.1 0.1"/>
      </geometry>
    </visual>
    <inertial>
      <mass value="0.06442"/>
      <inertia ixx="7.4993e-05" ixy="1.57e-09" ixz="-1.834e-08" iyy="7.6e-05" iyz="-5.295e-08" izz="5.53373e-06"/>
      <origin rpy="0 0 0" xyz="-1e-05 0 -0.02742"/>
    </inertial>
  </link>
  <joint name="HeadPitch" type="revolute">
    <parent link="Neck"/>
    <child link="Head"/>
    <origin rpy="0 0 0" xyz="0 0 0"/>
    <axis xyz="0 1.0 0"/>
    <limit effort="1.2" lower="-0.671952" upper="0.514872" velocity="7.19407"/>
  </joint>
  <link name="Head">
    <visual>
      <geometry>
        <mesh filename="file:///nao/V40/HeadPitch.mesh" scale="0.001 0.001 0.001"/>
      </geometry>
      <origin rpy="0 0 0" xyz="0 0 0"/>
    </visual>
    <inertial>
      <mass value="0.60533"/>
      <inertia ixx="0.0026313" ixy="8.78814e-06" ixz="4.09847e-05" iyy="0.00249112" iyz="-2.99579e-05" izz="0.000985736"/>
      <origin rpy="0 0 0" xyz="-0.00112 0 0.05258"/>
    </inertial>
  </link>
  <joint name="CameraTop_joint" type="fixed">
    <parent link="Head"/>
    <child link="CameraTop_frame"/>
    <origin rpy="0 0 0" xyz="0.0539 0 0.0679"/>
  </joint>
  <link name="CameraTop_frame"/>
  <joint name="gaze_joint" type="fixed">
    <parent link="CameraTop_frame"/>
    <child link="gaze"/>
    <origin rpy="0 0 0" xyz="0 0 0"/>
  </joint>
  <link name="gaze"/>
  <joint name="LHipYawPitch" type="revolute">
    <parent link="torso"/>
    <child link="LPelvis"/>
    <origin rpy="0 0 0" xyz="0 0.05 -0.085"/>
    <axis xyz="0 0.707106 -0.707106"/>
    <limit effort="3.2" lower="-1.14529" upper="0.740718" velocity="4.16174"/>
  </joint>
  <link name="LPelvis">
    <visual>
      <geometry>
        <mesh filename="file:///home/marguedas/.ros/nao_meshes/meshes/V40/visual/collada/LPelvis.dae" scale="0.1 0.1 0.1"/>
      </geometry>
    </visual>
    <inertial>
      <mass value="0.06981"/>
      <inertia ixx="8.15023e-05" ixy="-4.99449e-06" ixz="1.27482e-05" iyy="0.000101326" iyz="2.34547e-05" izz="6.26236e-05"/>
      <origin rpy="0 0 0" xyz="-0.00781 -0.01114 0.02661"/>
    </inertial>
  </link>
  <joint name="LHipRoll" type="revolute">
    <parent link="LPelvis"/>
    <child link="LHip"/>
    <origin rpy="0 0 0" xyz="0 0 0"/>
    <axis xyz="1.0 0 0"/>
    <limit effort="3.2" lower="-0.379435" upper="0.79046" velocity="4.16174"/>
  </joint>
  <link name="LHip">
    <visual>
      <geometry>
        <mesh filename="file:///home/marguedas/.ros/nao_meshes/meshes/V40/visual/collada/LHip.dae" scale="0.1 0.1 0.1"/>
      </geometry>
    </visual>
    <inertial>
      <mass value="0.13053"/>
      <inertia ixx="2.75835e-05" ixy="-2.233e-08" ixz="-4.08164e-06" iyy="9.82706e-05" iyz="-4.19e-09" izz="8.80997e-05"/>
      <origin rpy="0 0 0" xyz="-0.01549 0.00029 -0.00515"/>
    </inertial>
  </link>
  <joint name="LHipPitch" type="revolute">
    <parent link="LHip"/>
    <child link="LThigh"/>
    <origin rpy="0 0 0" xyz="0 0 0"/>
    <axis xyz="0 1.0 0"/>
    <limit effort="3.2" lower="-1.53589" upper="0.48398" velocity="6.40239"/>
  </joint>
  <link name="LThigh">
    <visual>
      <geometry>
        <mesh filename="file:///home/marguedas/.ros/nao_meshes/meshes/V40/visual/collada/LThigh.dae" scale="0.1 0.1 0.1"/>
      </geometry>
    </visual>
    <inertial>
      <mass value="0.38968"/>
      <inertia ixx="0.00163672" ixy="9.2451e-07" ixz="8.53067e-05" iyy="0.00159107" iyz="3.83616e-05" izz="0.000303743"/>
      <origin rpy="0 0 0" xyz="0.00138 0.00221 -0.05373"/>
    </inertial>
  </link>
  <joint name="LKneePitch" type="revolute">
    <parent link="LThigh"/>
    <child link="LTibia"/>
    <origin rpy="0 0 0" xyz="0 0 -0.1"/>
    <axis xyz="0 1.0 0"/>
    <limit effort="3.2" lower="-0.0923279" upper="2.11255" velocity="6.40239"/>
  </joint>
  <link name="LTibia">
    <visual>
      <geometry>
        <mesh filename="file:///home/marguedas/.ros/nao_meshes/meshes/V40/visual/collada/LTibia.dae" scale="0.1 0.1 0.1"/>
      </geometry>
    </visual>
    <inertial>
      <mass value="0.29142"/>
      <inertia ixx="0.00118208" ixy="6.3362e-07" ixz="3.6497e-05" iyy="0.00112865" iyz="3.94952e-05" izz="0.000193227"/>
      <origin rpy="0 0 0" xyz="0.00453 0.00225 -0.04936"/>
    </inertial>
  </link>
  <joint name="LAnklePitch" type="revolute">
    <parent link="LTibia"/>
    <child link="l_ankle"/>
    <origin rpy="0 0 0" xyz="0 0 -0.1029"/>
    <axis xyz="0 1.0 0"/>
    <limit effort="3.2" lower="-1.18944" upper="0.922581" velocity="6.40239"/>
  </joint>
  <link name="l_ankle">
    <visual>
      <geometry>
        <mesh filename="file:///home/marguedas/.ros/nao_meshes/meshes/V40/visual/collada/l_ankle.dae" scale="0.1 0.1 0.1"/>
      </geometry>
    </visual>
    <inertial>
      <mass value="0.13416"/>
      <inertia ixx="3.85098e-05" ixy="-2.634e-08" ixz="3.86194e-06" iyy="7.42653e-05" iyz="1.834e-08" izz="5.48654e-05"/>
      <origin rpy="0 0 0" xyz="0.00045 0.00029 0.00685"/>
    </inertial>
  </link>
  <joint name="l_sole_joint" type="fixed">
    <parent link="l_ankle"/>
    <child link="l_sole"/>
    <origin rpy="0 0 0" xyz="0 0 -0.04519"/>
  </joint>
  <link name="l_sole"/>
  <joint name="RHipYawPitch" type="revolute">
    <parent link="torso"/>
    <child link="RPelvis"/>
    <origin rpy="0 0 0" xyz="0 -0.05 -0.085"/>
    <axis xyz="0 0.707106 0.707106"/>
    <limit effort="3.2" lower="-1.14529" upper="0.740718" velocity="4.16174"/>
  </joint>
  <link name="RPelvis">
    <visual>
      <geometry>
        <mesh filename="file:///home/marguedas/.ros/nao_meshes/meshes/V40/visual/collada/RPelvis.dae" scale="0.1 0.1 0.1"/>
      </geometry>
    </visual>
    <inertial>
      <mass value="0.06981"/>
      <inertia ixx="8.9972e-05" ixy="5.00219e-06" ixz="1.27352e-05" iyy="0.000105526" iyz="-2.77008e-05" izz="6.68872e-05"/>
      <origin rpy="0 0 0" xyz="-0.00781 0.01114 0.02661"/>
    </inertial>
  </link>
  <joint name="RHipRoll" type="revolute">
    <parent link="RPelvis"/>
    <child link="RHip"/>
    <origin rpy="0 0 0" xyz="0 0 0"/>
    <axis xyz="1.0 0 0"/>
    <limit effort="3.2" lower="-0.79046" upper="0.379435" velocity="4.16174"/>
  </joint>
  <link name="RHip">
    <visual>
      <geometry>
        <mesh filename="file:///home/marguedas/.ros/nao_meshes/meshes/V40/visual/collada/RHip.dae" scale="0.1 0.1 0.1"/>
      </geometry>
    </visual>
    <inertial>
      <mass value="0.13053"/>
      <inertia ixx="2.75865e-05" ixy="-1.919e-08" ixz="-4.10822e-06" iyy="9.827e-05" iyz="2.51e-09" izz="8.81033e-05"/>
      <origin rpy="0 0 0" xyz="-0.01549 -0.00029 -0.00515"/>
    </inertial>
  </link>
  <joint name="RHipPitch" type="revolute">
    <parent link="RHip"/>
    <child link="RThigh"/>
    <origin rpy="0 0 0" xyz="0 0 0"/>
    <axis xyz="0 1.0 0"/>
    <limit effort="3.2" lower="-1.53589" upper="0.48398" velocity="6.40239"/>
  </joint>
  <link name="RThigh">
    <visual>
      <geometry>
        <mesh filename="file:///home/marguedas/.ros/nao_meshes/meshes/V40/visual/collada/RThigh.dae" scale="0.1 0.1 0.1"/>
      </geometry>
    </visual>
    <inertial>
      <mass value="0.38968"/>
      <inertia ixx="0.00163748" ixy="-8.3954e-07" ixz="8.5883e-05" iyy="0.00159221" iyz="-3.91763e-05" izz="0.000303978"/>
      <origin rpy="0 0 0" xyz="0.00138 -0.00221 -0.05373"/>
    </inertial>
  </link>
  <joint name="RKneePitch" type="revolute">
    <parent link="RThigh"/>
    <child link="RTibia"/>
    <origin rpy="0 0 0" xyz="0 0 -0.1"/>
    <axis xyz="0 1.0 0"/>
    <limit effort="3.2" lower="-0.0923279" upper="2.11255" velocity="6.40239"/>
  </joint>
  <link name="RTibia">
    <visual>
      <geometry>
        <mesh filename="file:///home/marguedas/.ros/nao_meshes/meshes/V40/visual/collada/RTibia.dae" scale="0.1 0.1 0.1"/>
      </geometry>
    </visual>
    <inertial>
      <mass value="0.29142"/>
      <inertia ixx="0.00118283" ixy="-8.965e-07" ixz="2.79969e-05" iyy="0.00112828" iyz="-3.8476e-05" izz="0.000191453"/>
      <origin rpy="0 0 0" xyz="0.00453 -0.00225 -0.04936"/>
    </inertial>
  </link>
  <joint name="RAnklePitch" type="revolute">
    <parent link="RTibia"/>
    <child link="r_ankle"/>
    <origin rpy="0 0 0" xyz="0 0 -0.1029"/>
    <axis xyz="0 1.0 0"/>
    <limit effort="3.2" lower="-1.1863" upper="0.932006" velocity="6.40239"/>
  </joint>
  <link name="r_ankle">
    <visual>
      <geometry>
        <mesh filename="file:///home/marguedas/.ros/nao_meshes/meshes/V40/visual/collada/r_ankle.dae" scale="0.1 0.1 0.1"/>
      </geometry>
    </visual>
    <inertial>
      <mass value="0.13416"/>
      <inertia ixx="3.85081e-05" ixy="6.434e-08" ixz="3.87466e-06" iyy="7.43108e-05" iyz="-4.58e-09" izz="5.49131e-05"/>
      <origin rpy="0 0 0" xyz="0.00045 -0.00029 0.00685"/>
    </inertial>
  </link>
  <joint name="r_sole_joint" type="fixed">
    <parent link="r_ankle"/>
    <child link="r_sole"/>
    <origin rpy="0 0 0" xyz="0 0 -0.04519"/>
  </joint>
  <link name="r_sole"/>
  <link name="base_link"/>
  <joint name="base_joint" type="fixed">
    <parent link="base_link"/>
    <child link="torso"/>
    <origin rpy="0 0 0" xyz="0 0 0"/>
  </joint>
  <link name="torso">
    <visual>
      <geometry>
        <mesh filename="file:///home/marguedas/.ros/nao_meshes/meshes/V40/visual/collada/torso.dae" scale="0.1 0.1 0.1"/>
      </geometry>
    </visual>
    <inertial>
      <mass value="1.04956"/>
      <inertia ixx="0.00506234" ixy="1.43116e-05" ixz="0.000155191" iyy="0.00488014" iyz="-2.70793e-05" izz="0.0016103"/>
      <origin rpy="0 0 0" xyz="-0.00413 0 0.04342"/>
    </inertial>
  </link>
  <joint name="LShoulderPitch" type="revolute">
    <parent link="torso"/>
    <child link="LShoulder"/>
    <origin rpy="0 0 0" xyz="0 0.098 0.1"/>
    <axis xyz="0 1.0 0"/>
    <limit effort="1.2" lower="-2.08567" upper="2.08567" velocity="8.26797"/>
  </joint>
  <link name="LShoulder">
    <visual>
      <geometry>
        <mesh filename="file:///home/marguedas/.ros/nao_meshes/meshes/V40/visual/collada/LShoulder.dae" scale="0.1 0.1 0.1"/>
      </geometry>
    </visual>
    <inertial>
      <mass value="0.07504"/>
      <inertia ixx="8.42843e-05" ixy="-2.02802e-06" ixz="2.338e-08" iyy="1.41556e-05" iyz="-1.972e-08" izz="8.64195e-05"/>
      <origin rpy="0 0 0" xyz="-0.00165 -0.02663 0.00014"/>
    </inertial>
  </link>
  <joint name="LShoulderRoll" type="revolute">
    <parent link="LShoulder"/>
    <child link="LBicep"/>
    <origin rpy="0 0 0" xyz="0 0 0"/>
    <axis xyz="0 0 1.0"/>
    <limit effort="1.2" lower="-0.314159" upper="1.32645" velocity="7.19407"/>
  </joint>
  <link name="LBicep">
    <visual>
      <geometry>
        <mesh filename="file:///home/marguedas/.ros/nao_meshes/meshes/V40/visual/collada/LBicep.dae" scale="0.1 0.1 0.1"/>
      </geometry>
    </visual>
    <inertial>
      <mass value="0.15777"/>
      <inertia ixx="9.38999e-05" ixy="-4.71445e-05" ixz="-2.69947e-05" iyy="0.000371519" iyz="-2.45977e-06" izz="0.000341901"/>
      <origin rpy="0 0 0" xyz="0.02455 0.00563 0.0033"/>
    </inertial>
  </link>
  <joint name="LElbowYaw" type="revolute">
    <parent link="LBicep"/>
    <child link="LElbow"/>
    <origin rpy="0 0 0" xyz="0.105 0.015 0"/>
    <axis xyz="1.0 0 0"/>
    <limit effort="1.2" lower="-2.08567" upper="2.08567" velocity="8.26797"/>
  </joint>
  <link name="LElbow">
    <inertial>
      <mass value="0.06483"/>
      <inertia ixx="5.59715e-06" ixy="4.21e-09" ixz="4.319e-08" iyy="7.54331e-05" iyz="-1.84e-09" izz="7.64434e-05"/>
      <origin rpy="0 0 0" xyz="-0.02744 0 -0.00014"/>
    </inertial>
  </link>
  <joint name="LElbowRoll" type="revolute">
    <parent link="LElbow"/>
    <child link="LForeArm"/>
    <origin rpy="0 0 0" xyz="0 0 0"/>
    <axis xyz="0 0 1.0"/>
    <limit effort="1.2" lower="-1.54462" upper="-0.0349066" velocity="7.19407"/>
  </joint>
  <link name="LForeArm">
    <visual>
      <geometry>
        <mesh filename="file:///home/marguedas/.ros/nao_meshes/meshes/V40/visual/collada/LForeArm.dae" scale="0.1 0.1 0.1"/>
      </geometry>
    </visual>
    <inertial>
      <mass value="0.07761"/>
      <inertia ixx="2.53322e-05" ixy="-2.34271e-06" ixz="7.459e-08" iyy="8.91322e-05" iyz="-2.655e-08" izz="8.72873e-05"/>
      <origin rpy="0 0 0" xyz="0.02556 0.00281 0.00076"/>
    </inertial>
  </link>
  <joint name="LWristYaw" type="revolute">
    <parent link="LForeArm"/>
    <child link="l_wrist"/>
    <origin rpy="0 0 0" xyz="0.05595 0 0"/>
    <axis xyz="1.0 0 0"/>
    <limit effort="0.76" lower="-1.82387" upper="1.82387" velocity="24.6229"/>
  </joint>
  <link name="l_wrist">
    <visual>
      <geometry>
        <mesh filename="file:///home/marguedas/.ros/nao_meshes/meshes/V40/visual/collada/l_wrist.dae" scale="0.1 0.1 0.1"/>
      </geometry>
    </visual>
    <inertial>
      <mass value="0.18533"/>
      <inertia ixx="7.05493e-05" ixy="5.71599e-06" ixz="-2.24744e-05" iyy="0.000356062" iyz="3.17771e-06" izz="0.000351919"/>
      <origin rpy="0 0 0" xyz="0.03434 -0.00088 0.00308"/>
    </inertial>
  </link>
  <joint name="LHand" type="fixed">
    <parent link="l_wrist"/>
    <child link="l_gripper"/>
    <origin rpy="0 0 0" xyz="0.05775 0 -0.01231"/>
  </joint>
  <link name="l_gripper">
    <visual>
      <geometry>
        <mesh filename="file:///home/marguedas/.ros/nao_meshes/meshes/V40/visual/collada/l_gripper.dae" scale="0.1 0.1 0.1"/>
      </geometry>
    </visual>
  </link>
  <joint name="RShoulderPitch" type="revolute">
    <parent link="torso"/>
    <child link="RShoulder"/>
    <origin rpy="0 0 0" xyz="0 -0.098 0.1"/>
    <axis xyz="0 1.0 0"/>
    <limit effort="1.2" lower="-2.08567" upper="2.08567" velocity="8.26797"/>
  </joint>
  <link name="RShoulder">
    <visual>
      <geometry>
        <mesh filename="file:///home/marguedas/.ros/nao_meshes/meshes/V40/visual/collada/RShoulder.dae" scale="0.1 0.1 0.1"/>
      </geometry>
    </visual>
    <inertial>
      <mass value="0.07504"/>
      <inertia ixx="8.42843e-05" ixy="2.02802e-06" ixz="2.338e-08" iyy="1.41556e-05" iyz="1.972e-08" izz="8.64195e-05"/>
      <origin rpy="0 0 0" xyz="-0.00165 0.02663 0.00014"/>
    </inertial>
  </link>
  <joint name="RShoulderRoll" type="revolute">
    <parent link="RShoulder"/>
    <child link="RBicep"/>
    <origin rpy="0 0 0" xyz="0 0 0"/>
    <axis xyz="0 0 1.0"/>
    <limit effort="1.2" lower="-1.32645" upper="0.314159" velocity="7.19407"/>
  </joint>
  <link name="RBicep">
    <visual>
      <geometry>
        <mesh filename="file:///home/marguedas/.ros/nao_meshes/meshes/V40/visual/collada/RBicep.dae" scale="0.1 0.1 0.1"/>
      </geometry>
    </visual>
    <inertial>
      <mass value="0.15777"/>
      <inertia ixx="0.00011012" ixy="7.66913e-05" ixz="-2.60461e-05" iyy="0.000367577" iyz="1.20983e-05" izz="0.000354618"/>
      <origin rpy="0 0 0" xyz="0.02455 -0.00563 0.0033"/>
    </inertial>
  </link>
  <joint name="RElbowYaw" type="revolute">
    <parent link="RBicep"/>
    <child link="RElbow"/>
    <origin rpy="0 0 0" xyz="0.105 -0.015 0"/>
    <axis xyz="1.0 0 0"/>
    <limit effort="1.2" lower="-2.08567" upper="2.08567" velocity="8.26797"/>
  </joint>
  <link name="RElbow">
    <inertial>
      <mass value="0.06483"/>
      <inertia ixx="5.59715e-06" ixy="4.21e-09" ixz="4.319e-08" iyy="7.54331e-05" iyz="-1.84e-09" izz="7.64434e-05"/>
      <origin rpy="0 0 0" xyz="-0.02744 0 -0.00014"/>
    </inertial>
  </link>
  <joint name="RElbowRoll" type="revolute">
    <parent link="RElbow"/>
    <child link="RForeArm"/>
    <origin rpy="0 0 0" xyz="0 0 0"/>
    <axis xyz="0 0 1.0"/>
    <limit effort="1.2" lower="0.0349066" upper="1.54462" velocity="7.19407"/>
  </joint>
  <link name="RForeArm">
    <visual>
      <geometry>
        <mesh filename="file:///home/marguedas/.ros/nao_meshes/meshes/V40/visual/collada/RForeArm.dae" scale="0.1 0.1 0.1"/>
      </geometry>
    </visual>
    <inertial>
      <mass value="0.07761"/>
      <inertia ixx="2.53907e-05" ixy="2.33243e-06" ixz="-6.0117e-07" iyy="8.92204e-05" iyz="2.694e-08" izz="8.72484e-05"/>
      <origin rpy="0 0 0" xyz="0.02556 -0.00281 0.00076"/>
    </inertial>
  </link>
  <joint name="RWristYaw" type="revolute">
    <parent link="RForeArm"/>
    <child link="r_wrist"/>
    <origin rpy="0 0 0" xyz="0.05595 0 0"/>
    <axis xyz="1.0 0 0"/>
    <limit effort="0.76" lower="-1.82387" upper="1.82387" velocity="24.6229"/>
  </joint>
  <link name="r_wrist">
    <visual>
      <geometry>
        <mesh filename="file:///home/marguedas/.ros/nao_meshes/meshes/V40/visual/collada/r_wrist.dae" scale="0.1 0.1 0.1"/>
      </geometry>
    </visual>
    <inertial>
      <mass value="0.18533"/>
      <inertia ixx="7.05493e-05" ixy="5.71599e-06" ixz="-2.24744e-05" iyy="0.000356062" iyz="3.17771e-06" izz="0.000351919"/>
      <origin rpy="0 0 0" xyz="0.03434 0.00088 0.00308"/>
    </inertial>
  </link>
  <joint name="RHand" type="fixed">
    <parent link="r_wrist"/>
    <child link="r_gripper"/>
    <origin rpy="0 0 0" xyz="0.05775 0 -0.01231"/>
  </joint>
  <link name="r_gripper">
    <visual>
      <geometry>
        <mesh filename="file:///home/marguedas/.ros/nao_meshes/meshes/V40/visual/collada/r_gripper.dae" scale="0.1 0.1 0.1"/>
      </geometry>
    </visual>
  </link>
  <gazebo reference="LThigh">
    <material>Gazebo/Red</material>
    <turnGravityOff>true</turnGravityOff>
    <mu1>0.5</mu1>
    <mu2>0.5</mu2>
    <selfCollide>false</selfCollide>
  </gazebo>
  <gazebo reference="l_wrist">
    <material>Gazebo/Red</material>
    <turnGravityOff>true</turnGravityOff>
    <mu1>0.5</mu1>
    <mu2>0.5</mu2>
    <selfCollide>false</selfCollide>
  </gazebo>
  <gazebo reference="RBicep">
    <material>Gazebo/Blue</material>
    <turnGravityOff>true</turnGravityOff>
    <mu1>0.5</mu1>
    <mu2>0.5</mu2>
    <selfCollide>false</selfCollide>
  </gazebo>
  <gazebo reference="l_gripper">
    <material>Gazebo/Red</material>
    <turnGravityOff>true</turnGravityOff>
    <mu1>0.5</mu1>
    <mu2>0.5</mu2>
    <selfCollide>false</selfCollide>
  </gazebo>
  <gazebo reference="r_sole">
    <material>Gazebo/Blue</material>
    <turnGravityOff>true</turnGravityOff>
    <mu1>0.5</mu1>
    <mu2>0.5</mu2>
    <selfCollide>false</selfCollide>
  </gazebo>
  <gazebo reference="RFeet">
    <material>Gazebo/Blue</material>
    <turnGravityOff>true</turnGravityOff>
    <mu1>0.5</mu1>
    <mu2>0.5</mu2>
    <selfCollide>false</selfCollide>
  </gazebo>
  <gazebo reference="Head">
    <material>Gazebo/Gray</material>
    <turnGravityOff>true</turnGravityOff>
    <mu1>0.5</mu1>
    <mu2>0.5</mu2>
    <selfCollide>false</selfCollide>
  </gazebo>
  <gazebo reference="RThigh">
    <material>Gazebo/Blue</material>
    <turnGravityOff>true</turnGravityOff>
    <mu1>0.5</mu1>
    <mu2>0.5</mu2>
    <selfCollide>false</selfCollide>
  </gazebo>
  <gazebo reference="r_ankle">
    <material>Gazebo/Blue</material>
    <turnGravityOff>true</turnGravityOff>
    <mu1>0.5</mu1>
    <mu2>0.5</mu2>
    <selfCollide>false</selfCollide>
  </gazebo>
  <gazebo reference="base_link">
    <material>Gazebo/Gray</material>
    <turnGravityOff>true</turnGravityOff>
    <mu1>0.5</mu1>
    <mu2>0.5</mu2>
    <selfCollide>false</selfCollide>
  </gazebo>
  <gazebo reference="LTibia">
    <material>Gazebo/Red</material>
    <turnGravityOff>true</turnGravityOff>
    <mu1>0.5</mu1>
    <mu2>0.5</mu2>
    <selfCollide>false</selfCollide>
  </gazebo>
  <gazebo reference="r_wrist">
    <material>Gazebo/Blue</material>
    <turnGravityOff>true</turnGravityOff>
    <mu1>0.5</mu1>
    <mu2>0.5</mu2>
    <selfCollide>false</selfCollide>
  </gazebo>
  <gazebo reference="gaze">
    <material>Gazebo/Gray</material>
    <turnGravityOff>true</turnGravityOff>
    <mu1>0.5</mu1>
    <mu2>0.5</mu2>
    <selfCollide>false</selfCollide>
  </gazebo>
  <gazebo reference="LElbow">
    <material>Gazebo/Red</material>
    <turnGravityOff>true</turnGravityOff>
    <mu1>0.5</mu1>
    <mu2>0.5</mu2>
    <selfCollide>false</selfCollide>
  </gazebo>
  <gazebo reference="RElbow">
    <material>Gazebo/Blue</material>
    <turnGravityOff>true</turnGravityOff>
    <mu1>0.5</mu1>
    <mu2>0.5</mu2>
    <selfCollide>false</selfCollide>
  </gazebo>
  <gazebo reference="l_ankle">
    <material>Gazebo/Red</material>
    <turnGravityOff>true</turnGravityOff>
    <mu1>0.5</mu1>
    <mu2>0.5</mu2>
    <selfCollide>false</selfCollide>
  </gazebo>
  <gazebo reference="Neck">
    <material>Gazebo/Gray</material>
    <turnGravityOff>true</turnGravityOff>
    <mu1>0.5</mu1>
    <mu2>0.5</mu2>
    <selfCollide>false</selfCollide>
  </gazebo>
  <gazebo reference="l_sole">
    <material>Gazebo/Red</material>
    <turnGravityOff>true</turnGravityOff>
    <mu1>0.5</mu1>
    <mu2>0.5</mu2>
    <selfCollide>false</selfCollide>
  </gazebo>
  <gazebo reference="LForeArm">
    <material>Gazebo/Red</material>
    <turnGravityOff>true</turnGravityOff>
    <mu1>0.5</mu1>
    <mu2>0.5</mu2>
    <selfCollide>false</selfCollide>
  </gazebo>
  <gazebo reference="RHip">
    <material>Gazebo/Blue</material>
    <turnGravityOff>true</turnGravityOff>
    <mu1>0.5</mu1>
    <mu2>0.5</mu2>
    <selfCollide>false</selfCollide>
  </gazebo>
  <gazebo reference="RForeArm">
    <material>Gazebo/Blue</material>
    <turnGravityOff>true</turnGravityOff>
    <mu1>0.5</mu1>
    <mu2>0.5</mu2>
    <selfCollide>false</selfCollide>
  </gazebo>
  <gazebo reference="r_gripper">
    <material>Gazebo/Blue</material>
    <turnGravityOff>true</turnGravityOff>
    <mu1>0.5</mu1>
    <mu2>0.5</mu2>
    <selfCollide>false</selfCollide>
  </gazebo>
  <gazebo reference="LBicep">
    <material>Gazebo/Red</material>
    <turnGravityOff>true</turnGravityOff>
    <mu1>0.5</mu1>
    <mu2>0.5</mu2>
    <selfCollide>false</selfCollide>
  </gazebo>
  <gazebo reference="RPelvis">
    <material>Gazebo/Blue</material>
    <turnGravityOff>true</turnGravityOff>
    <mu1>0.5</mu1>
    <mu2>0.5</mu2>
    <selfCollide>false</selfCollide>
  </gazebo>
  <gazebo reference="LShoulder">
    <material>Gazebo/Red</material>
    <turnGravityOff>true</turnGravityOff>
    <mu1>0.5</mu1>
    <mu2>0.5</mu2>
    <selfCollide>false</selfCollide>
  </gazebo>
  <gazebo reference="RTibia">
    <material>Gazebo/Blue</material>
    <turnGravityOff>true</turnGravityOff>
    <mu1>0.5</mu1>
    <mu2>0.5</mu2>
    <selfCollide>false</selfCollide>
  </gazebo>
  <gazebo reference="RShoulder">
    <material>Gazebo/Blue</material>
    <turnGravityOff>true</turnGravityOff>
    <mu1>0.5</mu1>
    <mu2>0.5</mu2>
    <selfCollide>false</selfCollide>
  </gazebo>
  <gazebo reference="LHip">
    <material>Gazebo/Red</material>
    <turnGravityOff>true</turnGravityOff>
    <mu1>0.5</mu1>
    <mu2>0.5</mu2>
    <selfCollide>false</selfCollide>
  </gazebo>
  <gazebo reference="LPelvis">
    <material>Gazebo/Red</material>
    <turnGravityOff>true</turnGravityOff>
    <mu1>0.5</mu1>
    <mu2>0.5</mu2>
    <selfCollide>false</selfCollide>
  </gazebo>
  <gazebo reference="LFeet">
    <material>Gazebo/Red</material>
    <turnGravityOff>true</turnGravityOff>
    <mu1>0.5</mu1>
    <mu2>0.5</mu2>
    <selfCollide>false</selfCollide>
  </gazebo>
  <gazebo reference="torso">
    <material>Gazebo/Gray</material>
    <turnGravityOff>true</turnGravityOff>
    <mu1>0.5</mu1>
    <mu2>0.5</mu2>
    <selfCollide>false</selfCollide>
  </gazebo>
</robot>

